Workbook

Sheet Resumo Geral
A1: RESUMO GERAL DE PORTAS
A3: MODELO / ABA DA PORTA | B3: TIPO DE PORTA | C3: CUSTO TOTAL DA PORTA (R$)
A4: PT PIVO GERIS EXT | B4: Pivotante | C4: ='PT PIVO GERIS EXT'!F26 -> 4182.6648
A5: PT PIVO GERIS INTERNA | B5: Pivotante | C5: ='PT PIVO GERIS INTERNA'!F27 -> 3060.1288
A6: PT PIVO GERIS WC | B6: Pivotante | C6: ='PT PIVO GERIS WC'!F27 -> 3258.9888
A7: PT PIVO ITALY LINE EXT | B7: Pivotante | C7: ='PT PIVO ITALY LINE EXT'!F26 -> 4454.4748
A8: PT PIVO ITALY LINE INT | B8: Pivotante | C8: ='PT PIVO ITALY LINE INT'!F27 -> 3291.9388
A9: PT PIVO ITALYNE WC | B9: Pivotante | C9: ='PT PIVO ITALYNE WC'!F27 -> 3490.7988
A10: PT PIVO CIR INTERNA. | B10: Pivotante | C10: ='PT PIVO CIR INTERNA'!F27 -> 3423.1638
A11: PT PIVO CIR WC | B11: Pivotante | C11: ='PT PIVO CIR WC'!F27 -> 3622.0238
A12: PT PASSAGEM INTERNA 3D | B12: Passagem | C12: ='PT PASSAGEM INTERNA 3D'!F27 -> 4624.5788
A13: PT PASSAGEM WC 3D | B13: Passagem | C13: ='PT PASSAGEM WC 3D'!F27 -> 5116.4388
A14: PT CORRER RO82 TOP INT | B14: Correr | C14: ='PT CORRER RO82 TOP INT'!F30 -> 4242.1348
A15: PT CORRER RO82 TOP WC | B15: Correr | C15: ='PT CORRER RO82 TOP WC'!F30 -> 4545.2848
A16: PORTA DE CORRER DN150 INT | B16: Correr | C16: ='PORTA CORRER DN150 INT'!F29 -> 4934.526
A17: PORTA CORRER DN150 WC | B17: Correr | C17: ='PORTA CORRER DN150 WC'!F30 -> 5158.386
B18: MÉDIA GERAL DE CUSTO: | C18: =AVERAGE(C4:C17) -> 4100.3951

Sheet Tabela de preços
A1: COMPOSIÇÃO DE CUSTOS - PT CORRER RO82 TOP WC.
A2: Base unificada de preços para cálculo de composições
A4: CÓDIGO | B4: DESCRIÇÃO PADRONIZADA | C4: UNID MEDIDA | D4: VALOR UNITÁRIO (R$)
A5: 865 | B5: LAMINA NATURAL CARVALHO EUROPEU | C5: M² | D5: 65
A6: PKT-MAT-865 | B6: LAMINA NATURAL CARVALHO EUROPEU | C6: M² | D6: 65
A7: PKT100024IN | B7: BUCHA 08MM | C7: CT | D7: 18
A8: PKT100033IN | B8: COLA DE CONTATO 2,8KG | C8: UNID | D8: 99
A9: PKT100039IN | B9: COLA PUR TEKBOND 500G | C9: UNID | D9: 33.64
A10: PKT100050IN | B10: VEDA FRESTAS 04 X 09MM MARROM CLARO C/ 06 MT | C10: UNID | D10: 18.51
A11: PKT100064IN | B11: FUNDO ACABAMENTO BRILHO 0 MILESSI | C11: LT | D11: 87.7068
A12: PKT100066IN | B12: COLA TITE BOND 1KG | C12: UNID | D12: 50.76
A13: PKT100070IN | B13: IMÃ 22X10 N.42 | C13: UNID | D13: 22.5
A14: PKT100218IN | B14: PINO F30 P/ PINADOR PNEUMATICO | C14: CT | D14: 0.452
A15: PKT100231IN | B15: PIVOT HEAVY H143 (300KG) AÇO ESCOVADO | C15: UNID | D15: 99.99
A16: PKT100285IN | B16: KIT RO 82TOP P/ 1 Porta FE9009 80-100kg | C16: KIT | D16: 473.5
... A39: PKT400351P | B39: MADEIRA MACIÇA TAUARI (0.02X0.30X3.00) | C39: UNID | D39: 52.2

Sheet PT PIVO GERIS EXT
A1: COMPOSIÇÃO DE CUSTOS - PT PIVO GERIS EXT
A2: Estrutura de custos por item integrada dinamicamente à Tabela de Preços
A4: CÓDIGO ITEM | B4: DESCRIÇÃO DO ITEM | C4: QUANTIDADE | D4: UNID MEDIDA | E4: CUSTO UNITÁRIO (R$) | F4: CUSTO TOTAL (R$)
A5: FERRAGENS
A6: PKT100231IN | B6: =IFERROR(VLOOKUP(A6, 'Tabela de preços'!A:D, 2, FALSE), "") -> PIVOT HEAVY H143 (300KG) AÇO ESCOVADO | C6: 1 | D6: =IFERROR(VLOOKUP(A6, 'Tabela de preços'!A:D, 3, FALSE), "") -> UNID | E6: =IFERROR(VLOOKUP(A6, 'Tabela de preços'!A:D, 4, FALSE), 0) -> 99.99 | F6: =C6*E6 -> 99.99
A7: PKT100050IN | B7: =IFERROR(VLOOKUP(A7, 'Tabela de preços'!A:D, 2, FALSE), "") -> VEDA FRESTAS 04 X 09MM MARROM CLARO C/ 06 MT | C7: 1 | D7: =IFERROR(VLOOKUP(A7, 'Tabela de preços'!A:D, 3, FALSE), "") -> UNID | E7: =IFERROR(VLOOKUP(A7, 'Tabela de preços'!A:D, 4, FALSE), 0) -> 18.51 | F7: =C7*E7 -> 18.51
A8: PKT100070IN | B8: =IFERROR(VLOOKUP(A8, 'Tabela de preços'!A:D, 2, FALSE), "") -> IMÃ 22X10 N.42 | C8: 4 | D8: =IFERROR(VLOOKUP(A8, 'Tabela de preços'!A:D, 3, FALSE), "") -> UNID | E8: =IFERROR(VLOOKUP(A8, 'Tabela de preços'!A:D, 4, FALSE), 0) -> 22.5 | F8: =C8*E8 -> 90
A9: PKT100633IN | B9: =IFERROR(VLOOKUP(A9, 'Tabela de preços'!A:D, 2, FALSE), "") -> FECHADURA SEGURANÇA 12 PINOS C/ ROLETE 70200 KESO | C9: 1 | D9: =IFERROR(VLOOKUP(A9, 'Tabela de preços'!A:D, 3, FALSE), "") -> CJ | E9: =IFERROR(VLOOKUP(A9, 'Tabela de preços'!A:D, 4, FALSE), 0) -> 1301 | F9: =C9*E9 -> 1301
A10: PKT100522IN | B10: =IFERROR(VLOOKUP(A10, 'Tabela de preços'!A:D, 2, FALSE), "") -> COLAR OBLONGO ACABAMENTO CHAVE 27,5x13mm | C10: 1 | D10: =IFERROR(VLOOKUP(A10, 'Tabela de preços'!A:D, 3, FALSE), "") -> UNID | E10: =IFERROR(VLOOKUP(A10, 'Tabela de preços'!A:D, 4, FALSE), 0) -> 40 | F10: =C10*E10 -> 40
A11: MATÉRIA PRIMA
A12: PKT100520IN | B12: =IFERROR(VLOOKUP(A12, 'Tabela de preços'!A:D, 2, FALSE), "") -> COMPENSADO NAVAL 10MM (10X1200X3000) | C12: 2 | D12: =IFERROR(VLOOKUP(A12, 'Tabela de preços'!A:D, 3, FALSE), "") -> UNID | E12: =IFERROR(VLOOKUP(A12, 'Tabela de preços'!A:D, 4, FALSE), 0) -> 185 | F12: =C12*E12 -> 370
A13: PKT-MAT-865 | B13: =IFERROR(VLOOKUP(A13, 'Tabela de preços'!A:D, 2, FALSE), "") -> LAMINA NATURAL CARVALHO EUROPEU | C13: 20 | D13: =IFERROR(VLOOKUP(A13, 'Tabela de preços'!A:D, 3, FALSE), "") -> M² | E13: =IFERROR(VLOOKUP(A13, 'Tabela de preços'!A:D, 4, FALSE), 0) -> 65 | F13: =C13*E13 -> 1300
A14: PKT400351P | B14: =IFERROR(VLOOKUP(A14, 'Tabela de preços'!A:D, 2, FALSE), "") -> MADEIRA MACIÇA TAUARI (0.02X0.30X3.00) | C14: 5 | D14: =IFERROR(VLOOKUP(A14, 'Tabela de preços'!A:D, 3, FALSE), "") -> UNID | E14: =IFERROR(VLOOKUP(A14, 'Tabela de preços'!A:D, 4, FALSE), 0) -> 52.2 | F14: =C14*E14 -> 261
A15: PKT100520IN | B15: =IFERROR(VLOOKUP(A15, 'Tabela de preços'!A:D, 2, FALSE), "") -> COMPENSADO NAVAL 10MM (10X1200X3000) | C15: 1.56 | D15: =IFERROR(VLOOKUP(A15, 'Tabela de preços'!A:D, 3, FALSE), "") -> UNID | E15: =IFERROR(VLOOKUP(A15, 'Tabela de preços'!A:D, 4, FALSE), 0) -> 185 | F15: =C15*E15 -> 288.6
A16: PKT100066IN | B16: =IFERROR(VLOOKUP(A16, 'Tabela de preços'!A:D, 2, FALSE), "") -> COLA TITE BOND 1KG | C16: 1.6 | D16: =IFERROR(VLOOKUP(A16, 'Tabela de preços'!A:D, 3, FALSE), "") -> UNID | E16: =IFERROR(VLOOKUP(A16, 'Tabela de preços'!A:D, 4, FALSE), 0) -> 50.76 | F16: =C16*E16 -> 81.216
A17: PKT100487IN | B17: =IFERROR(VLOOKUP(A17, 'Tabela de preços'!A:D, 2, FALSE), "") -> BARRA TUBO 20 X 30 X 6,00 CH PRETO | C17: 3 | D17: =IFERROR(VLOOKUP(A17, 'Tabela de preços'!A:D, 3, FALSE), "") -> BARRA | E17: =IFERROR(VLOOKUP(A17, 'Tabela de preços'!A:D, 4, FALSE), 0) -> 66.45 | F17: =C17*E17 -> 199.35
A18: PKT100064IN | B18: =IFERROR(VLOOKUP(A18, 'Tabela de preços'!A:D, 2, FALSE), "") -> FUNDO ACABAMENTO BRILHO 0 MILESSI | C18: 1 | D18: =IFERROR(VLOOKUP(A18, 'Tabela de preços'!A:D, 3, FALSE), "") -> LT | E18: =IFERROR(VLOOKUP(A18, 'Tabela de preços'!A:D, 4, FALSE), 0) -> 87.7068 | F18: =C18*E18 -> 87.7068
A19: PKT100039IN | B19: =IFERROR(VLOOKUP(A19, 'Tabela de preços'!A:D, 2, FALSE), "") -> COLA PUR TEKBOND 500G | C19: 1 | D19: =IFERROR(VLOOKUP(A19, 'Tabela de preços'!A:D, 3, FALSE), "") -> UNID | E19: =IFERROR(VLOOKUP(A19, 'Tabela de preços'!A:D, 4, FALSE), 0) -> 33.64 | F19: =C19*E19 -> 33.64
A20: PKT100504IN | B20: =IFERROR(VLOOKUP(A20, 'Tabela de preços'!A:D, 2, FALSE), "") -> GRAMPO TIPO ''U'' 80x12MM | C20: 1 | D20: =IFERROR(VLOOKUP(A20, 'Tabela de preços'!A:D, 3, FALSE), "") -> CT | E20: =IFERROR(VLOOKUP(A20, 'Tabela de preços'!A:D, 4, FALSE), 0) -> 2 | F20: =C20*E20 -> 2
A21: PKT100218IN | B21: =IFERROR(VLOOKUP(A21, 'Tabela de preços'!A:D, 2, FALSE), "") -> PINO F30 P/ PINADOR PNEUMATICO | C21: 1 | D21: =IFERROR(VLOOKUP(A21, 'Tabela de preços'!A:D, 3, FALSE), "") -> CT | E21: =IFERROR(VLOOKUP(A21, 'Tabela de preços'!A:D, 4, FALSE), 0) -> 0.452 | F21: =C21*E21 -> 0.452
A22: INSUMOS DE OBRA
A23: PKT100521IN | B23: =IFERROR(VLOOKUP(A23, 'Tabela de preços'!A:D, 2, FALSE), "") -> PARAFUSO BICROMATIZADO PHILIPS 6.0X80MM | C23: 0.2 | D23: =IFERROR(VLOOKUP(A23, 'Tabela de preços'!A:D, 3, FALSE), "") -> CT | E23: =IFERROR(VLOOKUP(A23, 'Tabela de preços'!A:D, 4, FALSE), 0) -> 28 | F23: =C23*E23 -> 5.6
A24: PKT100024IN | B24: =IFERROR(VLOOKUP(A24, 'Tabela de preços'!A:D, 2, FALSE), "") -> BUCHA 08MM | C24: 0.2 | D24: =IFERROR(VLOOKUP(A24, 'Tabela de preços'!A:D, 3, FALSE), "") -> CT | E24: =IFERROR(VLOOKUP(A24, 'Tabela de preços'!A:D, 4, FALSE), 0) -> 18 | F24: =C24*E24 -> 3.6
E26: CUSTO TOTAL DA PORTA: | F26: =SUM(F5:F24) -> 4182.6648

Sheet PT PIVO GERIS INTERNA
A1: COMPOSIÇÃO DE CUSTOS - PT PIVO GERIS INTERNA
A2: Estrutura de custos por item integrada dinamicamente à Tabela de Preços
A4: CÓDIGO ITEM | B4: DESCRIÇÃO DO ITEM | C4: QUANTIDADE | D4: UNID MEDIDA | E4: CUSTO UNITÁRIO (R$) | F4: CUSTO TOTAL (R$)
A5: FERRAGENS
A6: PKT100231IN | B6: =IFERROR(VLOOKUP(A6, 'Tabela de preços'!A:D, 2, FALSE), "") -> PIVOT HEAVY H143 (300KG) AÇO ESCOVADO | C6: 1 | D6: =IFERROR(VLOOKUP(A6, 'Tabela de preços'!A:D, 3, FALSE), "") -> UNID | E6: =IFERROR(VLOOKUP(A6, 'Tabela de preços'!A:D, 4, FALSE), 0) -> 99.99 | F6: =C6*E6 -> 99.99
A7: PKT100050IN | B7: =IFERROR(VLOOKUP(A7, 'Tabela de preços'!A:D, 2, FALSE), "") -> VEDA FRESTAS 04 X 09MM MARROM CLARO C/ 06 MT | C7: 1 | D7: =IFERROR(VLOOKUP(A7, 'Tabela de preços'!A:D, 3, FALSE), "") -> UNID | E7: =IFERROR(VLOOKUP(A7, 'Tabela de preços'!A:D, 4, FALSE), 0) -> 18.51 | F7: =C7*E7 -> 18.51
A8: PKT100070IN | B8: =IFERROR(VLOOKUP(A8, 'Tabela de preços'!A:D, 2, FALSE), "") -> IMÃ 22X10 N.42 | C8: 4 | D8: =IFERROR(VLOOKUP(A8, 'Tabela de preços'!A:D, 3, FALSE), "") -> UNID | E8: =IFERROR(VLOOKUP(A8, 'Tabela de preços'!A:D, 4, FALSE), 0) -> 22.5 | F8: =C8*E8 -> 90
A9: PKT100519IN | B9: =IFERROR(VLOOKUP(A9, 'Tabela de preços'!A:D, 2, FALSE), "") -> ADAPTADOR INTERNO, PARA FECHADURAS COD 911.03.886 | C9: 1 | D9: =IFERROR(VLOOKUP(A9, 'Tabela de preços'!A:D, 3, FALSE), "") -> UNID | E9: =IFERROR(VLOOKUP(A9, 'Tabela de preços'!A:D, 4, FALSE), 0) -> 33.26 | F9: =C9*E9 -> 33.26
A10: PKT100505IN | B10: =IFERROR(VLOOKUP(A10, 'Tabela de preços'!A:D, 2, FALSE), "") -> FECHADURA AUX LINGUETA RETA INOX FOSCO 911.22.490 | C10: 1 | D10: =IFERROR(VLOOKUP(A10, 'Tabela de preços'!A:D, 3, FALSE), "") -> UNID | E10: =IFERROR(VLOOKUP(A10, 'Tabela de preços'!A:D, 4, FALSE), 0) -> 105.204 | F10: =C10*E10 -> 105.204
A11: PKT100522IN | B11: =IFERROR(VLOOKUP(A11, 'Tabela de preços'!A:D, 2, FALSE), "") -> COLAR OBLONGO ACABAMENTO CHAVE 27,5x13mm | C11: 2 | D11: =IFERROR(VLOOKUP(A11, 'Tabela de preços'!A:D, 3, FALSE), "") -> UNID | E11: =IFERROR(VLOOKUP(A11, 'Tabela de preços'!A:D, 4, FALSE), 0) -> 40 | F11: =C11*E11 -> 80
A12: MATÉRIA PRIMA
A13: PKT100520IN | B13: =IFERROR(VLOOKUP(A13, 'Tabela de preços'!A:D, 2, FALSE), "") -> COMPENSADO NAVAL 10MM (10X1200X3000) | C13: 2 | D13: =IFERROR(VLOOKUP(A13, 'Tabela de preços'!A:D, 3, FALSE), "") -> UNID | E13: =IFERROR(VLOOKUP(A13, 'Tabela de preços'!A:D, 4, FALSE), 0) -> 185 | F13: =C13*E13 -> 370
A14: PKT-MAT-865 | B14: =IFERROR(VLOOKUP(A14, 'Tabela de preços'!A:D, 2, FALSE), "") -> LAMINA NATURAL CARVALHO EUROPEU | C14: 20 | D14: =IFERROR(VLOOKUP(A14, 'Tabela de preços'!A:D, 3, FALSE), "") -> M² | E14: =IFERROR(VLOOKUP(A14, 'Tabela de preços'!A:D, 4, FALSE), 0) -> 65 | F14: =C14*E14 -> 1300
A15: PKT400351P | B15: =IFERROR(VLOOKUP(A15, 'Tabela de preços'!A:D, 2, FALSE), "") -> MADEIRA MACIÇA TAUARI (0.02X0.30X3.00) | C15: 5 | D15: =IFERROR(VLOOKUP(A15, 'Tabela de preços'!A:D, 3, FALSE), "") -> UNID | E15: =IFERROR(VLOOKUP(A15, 'Tabela de preços'!A:D, 4, FALSE), 0) -> 52.2 | F15: =C15*E15 -> 261
A16: PKT100520IN | B16: =IFERROR(VLOOKUP(A16, 'Tabela de preços'!A:D, 2, FALSE), "") -> COMPENSADO NAVAL 10MM (10X1200X3000) | C16: 1.56 | D16: =IFERROR(VLOOKUP(A16, 'Tabela de preços'!A:D, 3, FALSE), "") -> UNID | E16: =IFERROR(VLOOKUP(A16, 'Tabela de preços'!A:D, 4, FALSE), 0) -> 185 | F16: =C16*E16 -> 288.6
A17: PKT100066IN | B17: =IFERROR(VLOOKUP(A17, 'Tabela de preços'!A:D, 2, FALSE), "") -> COLA TITE BOND 1KG | C17: 1.6 | D17: =IFERROR(VLOOKUP(A17, 'Tabela de preços'!A:D, 3, FALSE), "") -> UNID | E17: =IFERROR(VLOOKUP(A17, 'Tabela de preços'!A:D, 4, FALSE), 0) -> 50.76 | F17: =C17*E17 -> 81.216
A18: PKT100487IN | B18: =IFERROR(VLOOKUP(A18, 'Tabela de preços'!A:D, 2, FALSE), "") -> BARRA TUBO 20 X 30 X 6,00 CH PRETO | C18: 3 | D18: =IFERROR(VLOOKUP(A18, 'Tabela de preços'!A:D, 3, FALSE), "") -> BARRA | E18: =IFERROR(VLOOKUP(A18, 'Tabela de preços'!A:D, 4, FALSE), 0) -> 66.45 | F18: =C18*E18 -> 199.35
A19: PKT100064IN | B19: =IFERROR(VLOOKUP(A19, 'Tabela de preços'!A:D, 2, FALSE), "") -> FUNDO ACABAMENTO BRILHO 0 MILESSI | C19: 1 | D19: =IFERROR(VLOOKUP(A19, 'Tabela de preços'!A:D, 3, FALSE), "") -> LT | E19: =IFERROR(VLOOKUP(A19, 'Tabela de preços'!A:D, 4, FALSE), 0) -> 87.7068 | F19: =C19*E19 -> 87.7068
A20: PKT100039IN | B20: =IFERROR(VLOOKUP(A20, 'Tabela de preços'!A:D, 2, FALSE), "") -> COLA PUR TEKBOND 500G | C20: 1 | D20: =IFERROR(VLOOKUP(A20, 'Tabela de preços'!A:D, 3, FALSE), "") -> UNID | E20: =IFERROR(VLOOKUP(A20, 'Tabela de preços'!A:D, 4, FALSE), 0) -> 33.64 | F20: =C20*E20 -> 33.64
A21: PKT100504IN | B21: =IFERROR(VLOOKUP(A21, 'Tabela de preços'!A:D, 2, FALSE), "") -> GRAMPO TIPO ''U'' 80x12MM | C21: 1 | D21: =IFERROR(VLOOKUP(A21, 'Tabela de preços'!A:D, 3, FALSE), "") -> CT | E21: =IFERROR(VLOOKUP(A21, 'Tabela de preços'!A:D, 4, FALSE), 0) -> 2 | F21: =C21*E21 -> 2
A22: PKT100218IN | B22: =IFERROR(VLOOKUP(A22, 'Tabela de preços'!A:D, 2, FALSE), "") -> PINO F30 P/ PINADOR PNEUMATICO | C22: 1 | D22: =IFERROR(VLOOKUP(A22, 'Tabela de preços'!A:D, 3, FALSE), "") -> CT | E22: =IFERROR(VLOOKUP(A22, 'Tabela de preços'!A:D, 4, FALSE), 0) -> 0.452 | F22: =C22*E22 -> 0.452
A23: INSUMOS DE OBRA
A24: PKT100521IN | B24: =IFERROR(VLOOKUP(A24, 'Tabela de preços'!A:D, 2, FALSE), "") -> PARAFUSO BICROMATIZADO PHILIPS 6.0X80MM | C24: 0.2 | D24: =IFERROR(VLOOKUP(A24, 'Tabela de preços'!A:D, 3, FALSE), "") -> CT | E24: =IFERROR(VLOOKUP(A24, 'Tabela de preços'!A:D, 4, FALSE), 0) -> 28 | F24: =C24*E24 -> 5.6
A25: PKT100024IN | B25: =IFERROR(VLOOKUP(A25, 'Tabela de preços'!A:D, 2, FALSE), "") -> BUCHA 08MM | C25: 0.2 | D25: =IFERROR(VLOOKUP(A25, 'Tabela de preços'!A:D, 3, FALSE), "") -> CT | E25: =IFERROR(VLOOKUP(A25, 'Tabela de preços'!A:D, 4, FALSE), 0) -> 18 | F25: =C25*E25 -> 3.6
E27: CUSTO TOTAL DA PORTA: | F27: =SUM(F5:F25) -> 3060.1288

Sheet PT PIVO GERIS WC
A1: COMPOSIÇÃO DE CUSTOS - PT PIVO GERIS WC
A2: Estrutura de custos por item integrada dinamicamente à Tabela de Preços
A4: CÓDIGO ITEM | B4: DESCRIÇÃO DO ITEM | C4: QUANTIDADE | D4: UNID MEDIDA | E4: CUSTO UNITÁRIO (R$) | F4: CUSTO TOTAL (R$)
A5: FERRAGENS
A6: PKT100231IN | B6: =IFERROR(VLOOKUP(A6, 'Tabela de preços'!A:D, 2, FALSE), "") -> PIVOT HEAVY H143 (300KG) AÇO ESCOVADO | C6: 1 | D6: =IFERROR(VLOOKUP(A6, 'Tabela de preços'!A:D, 3, FALSE), "") -> UNID | E6: =IFERROR(VLOOKUP(A6, 'Tabela de preços'!A:D, 4, FALSE), 0) -> 99.99 | F6: =C6*E6 -> 99.99
A7: PKT100050IN | B7: =IFERROR(VLOOKUP(A7, 'Tabela de preços'!A:D, 2, FALSE), "") -> VEDA FRESTAS 04 X 09MM MARROM CLARO C/ 06 MT | C7: 1 | D7: =IFERROR(VLOOKUP(A7, 'Tabela de preços'!A:D, 3, FALSE), "") -> UNID | E7: =IFERROR(VLOOKUP(A7, 'Tabela de preços'!A:D, 4, FALSE), 0) -> 18.51 | F7: =C7*E7 -> 18.51
A8: PKT100070IN | B8: =IFERROR(VLOOKUP(A8, 'Tabela de preços'!A:D, 2, FALSE), "") -> IMÃ 22X10 N.42 | C8: 4 | D8: =IFERROR(VLOOKUP(A8, 'Tabela de preços'!A:D, 3, FALSE), "") -> UNID | E8: =IFERROR(VLOOKUP(A8, 'Tabela de preços'!A:D, 4, FALSE), 0) -> 22.5 | F8: =C8*E8 -> 90
A9: PKT100505IN | B9: =IFERROR(VLOOKUP(A9, 'Tabela de preços'!A:D, 2, FALSE), "") -> FECHADURA AUX LINGUETA RETA INOX FOSCO 911.22.490 | C9: 1 | D9: =IFERROR(VLOOKUP(A9, 'Tabela de preços'!A:D, 3, FALSE), "") -> UNID | E9: =IFERROR(VLOOKUP(A9, 'Tabela de preços'!A:D, 4, FALSE), 0) -> 105.204 | F9: =C9*E9 -> 105.204
A10: PKT100506IN | B10: =IFERROR(VLOOKUP(A10, 'Tabela de preços'!A:D, 2, FALSE), "") -> ADAPTADOR P/WC ZMK NIQ 911.03.885 | C10: 1 | D10: =IFERROR(VLOOKUP(A10, 'Tabela de preços'!A:D, 3, FALSE), "") -> UNID | E10: =IFERROR(VLOOKUP(A10, 'Tabela de preços'!A:D, 4, FALSE), 0) -> 19.12 | F10: =C10*E10 -> 19.12
A11: PKT100512IN | B11: =IFERROR(VLOOKUP(A11, 'Tabela de preços'!A:D, 2, FALSE), "") -> TRANQUETA GOTINHA AÇO INOX ESCOVADO | C11: 1 | D11: =IFERROR(VLOOKUP(A11, 'Tabela de preços'!A:D, 3, FALSE), "") -> UNID | E11: =IFERROR(VLOOKUP(A11, 'Tabela de preços'!A:D, 4, FALSE), 0) -> 293 | F11: =C11*E11 -> 293
A12: MATÉRIA PRIMA
A13: PKT100520IN | B13: =IFERROR(VLOOKUP(A13, 'Tabela de preços'!A:D, 2, FALSE), "") -> COMPENSADO NAVAL 10MM (10X1200X3000) | C13: 2 | D13: =IFERROR(VLOOKUP(A13, 'Tabela de preços'!A:D, 3, FALSE), "") -> UNID | E13: =IFERROR(VLOOKUP(A13, 'Tabela de preços'!A:D, 4, FALSE), 0) -> 185 | F13: =C13*E13 -> 370
A14: PKT-MAT-865 | B14: =IFERROR(VLOOKUP(A14, 'Tabela de preços'!A:D, 2, FALSE), "") -> LAMINA NATURAL CARVALHO EUROPEU | C14: 20 | D14: =IFERROR(VLOOKUP(A14, 'Tabela de preços'!A:D, 3, FALSE), "") -> M² | E14: =IFERROR(VLOOKUP(A14, 'Tabela de preços'!A:D, 4, FALSE), 0) -> 65 | F14: =C14*E14 -> 1300
A15: PKT400351P | B15: =IFERROR(VLOOKUP(A15, 'Tabela de preços'!A:D, 2, FALSE), "") -> MADEIRA MACIÇA TAUARI (0.02X0.30X3.00) | C15: 5 | D15: =IFERROR(VLOOKUP(A15, 'Tabela de preços'!A:D, 3, FALSE), "") -> UNID | E15: =IFERROR(VLOOKUP(A15, 'Tabela de preços'!A:D, 4, FALSE), 0) -> 52.2 | F15: =C15*E15 -> 261
A16: PKT100520IN | B16: =IFERROR(VLOOKUP(A16, 'Tabela de preços'!A:D, 2, FALSE), "") -> COMPENSADO NAVAL 10MM (10X1200X3000) | C16: 1.56 | D16: =IFERROR(VLOOKUP(A16, 'Tabela de preços'!A:D, 3, FALSE), "") -> UNID | E16: =IFERROR(VLOOKUP(A16, 'Tabela de preços'!A:D, 4, FALSE), 0) -> 185 | F16: =C16*E16 -> 288.6
A17: PKT100066IN | B17: =IFERROR(VLOOKUP(A17, 'Tabela de preços'!A:D, 2, FALSE), "") -> COLA TITE BOND 1KG | C17: 1.6 | D17: =IFERROR(VLOOKUP(A17, 'Tabela de preços'!A:D, 3, FALSE), "") -> UNID | E17: =IFERROR(VLOOKUP(A17, 'Tabela de preços'!A:D, 4, FALSE), 0) -> 50.76 | F17: =C17*E17 -> 81.216
A18: PKT100487IN | B18: =IFERROR(VLOOKUP(A18, 'Tabela de preços'!A:D, 2, FALSE), "") -> BARRA TUBO 20 X 30 X 6,00 CH PRETO | C18: 3 | D18: =IFERROR(VLOOKUP(A18, 'Tabela de preços'!A:D, 3, FALSE), "") -> BARRA | E18: =IFERROR(VLOOKUP(A18, 'Tabela de preços'!A:D, 4, FALSE), 0) -> 66.45 | F18: =C18*E18 -> 199.35
A19: PKT100064IN | B19: =IFERROR(VLOOKUP(A19, 'Tabela de preços'!A:D, 2, FALSE), "") -> FUNDO ACABAMENTO BRILHO 0 MILESSI | C19: 1 | D19: =IFERROR(VLOOKUP(A19, 'Tabela de preços'!A:D, 3, FALSE), "") -> LT | E19: =IFERROR(VLOOKUP(A19, 'Tabela de preços'!A:D, 4, FALSE), 0) -> 87.7068 | F19: =C19*E19 -> 87.7068
A20: PKT100039IN | B20: =IFERROR(VLOOKUP(A20, 'Tabela de preços'!A:D, 2, FALSE), "") -> COLA PUR TEKBOND 500G | C20: 1 | D20: =IFERROR(VLOOKUP(A20, 'Tabela de preços'!A:D, 3, FALSE), "") -> UNID | E20: =IFERROR(VLOOKUP(A20, 'Tabela de preços'!A:D, 4, FALSE), 0) -> 33.64 | F20: =C20*E20 -> 33.64
A21: PKT100504IN | B21: =IFERROR(VLOOKUP(A21, 'Tabela de preços'!A:D, 2, FALSE), "") -> GRAMPO TIPO ''U'' 80x12MM | C21: 1 | D21: =IFERROR(VLOOKUP(A21, 'Tabela de preços'!A:D, 3, FALSE), "") -> CT | E21: =IFERROR(VLOOKUP(A21, 'Tabela de preços'!A:D, 4, FALSE), 0) -> 2 | F21: =C21*E21 -> 2
A22: PKT100218IN | B22: =IFERROR(VLOOKUP(A22, 'Tabela de preços'!A:D, 2, FALSE), "") -> PINO F30 P/ PINADOR PNEUMATICO | C22: 1 | D22: =IFERROR(VLOOKUP(A22, 'Tabela de preços'!A:D, 3, FALSE), "") -> CT | E22: =IFERROR(VLOOKUP(A22, 'Tabela de preços'!A:D, 4, FALSE), 0) -> 0.452 | F22: =C22*E22 -> 0.452
A23: INSUMOS DE OBRA
A24: PKT100521IN | B24: =IFERROR(VLOOKUP(A24, 'Tabela de preços'!A:D, 2, FALSE), "") -> PARAFUSO BICROMATIZADO PHILIPS 6.0X80MM | C24: 0.2 | D24: =IFERROR(VLOOKUP(A24, 'Tabela de preços'!A:D, 3, FALSE), "") -> CT | E24: =IFERROR(VLOOKUP(A24, 'Tabela de preços'!A:D, 4, FALSE), 0) -> 28 | F24: =C24*E24 -> 5.6
A25: PKT100024IN | B25: =IFERROR(VLOOKUP(A25, 'Tabela de preços'!A:D, 2, FALSE), "") -> BUCHA 08MM | C25: 0.2 | D25: =IFERROR(VLOOKUP(A25, 'Tabela de preços'!A:D, 3, FALSE), "") -> CT | E25: =IFERROR(VLOOKUP(A25, 'Tabela de preços'!A:D, 4, FALSE), 0) -> 18 | F25: =C25*E25 -> 3.6
E27: CUSTO TOTAL DA PORTA: | F27: =SUM(F5:F25) -> 3258.9888

Sheet PT PIVO ITALY LINE EXT
A1: COMPOSIÇÃO DE CUSTOS - PT PIVO ITALY LINE EXT
A2: Estrutura de custos por item integrada dinamicamente à Tabela de Preços
A4: CÓDIGO ITEM | B4: DESCRIÇÃO DO ITEM | C4: QUANTIDADE | D4: UNID MEDIDA | E4: CUSTO UNITÁRIO (R$) | F4: CUSTO TOTAL (R$)
A5: FERRAGENS
A6: PKT100297IN | B6: =IFERROR(VLOOKUP(A6, 'Tabela de preços'!A:D, 2, FALSE), "") -> PIVOT IL 100 (INVISIVEL) 280KG - ITALY LINE | C6: 1 | D6: =IFERROR(VLOOKUP(A6, 'Tabela de preços'!A:D, 3, FALSE), "") -> UNID | E6: =IFERROR(VLOOKUP(A6, 'Tabela de preços'!A:D, 4, FALSE), 0) -> 331.8 | F6: =C6*E6 -> 331.8
A7: PKT100050IN | B7: =IFERROR(VLOOKUP(A7, 'Tabela de preços'!A:D, 2, FALSE), "") -> VEDA FRESTAS 04 X 09MM MARROM CLARO C/ 06 MT | C7: 1 | D7: =IFERROR(VLOOKUP(A7, 'Tabela de preços'!A:D, 3, FALSE), "") -> UNID | E7: =IFERROR(VLOOKUP(A7, 'Tabela de preços'!A:D, 4, FALSE), 0) -> 18.51 | F7: =C7*E7 -> 18.51
A8: PKT100070IN | B8: =IFERROR(VLOOKUP(A8, 'Tabela de preços'!A:D, 2, FALSE), "") -> IMÃ 22X10 N.42 | C8: 4 | D8: =IFERROR(VLOOKUP(A8, 'Tabela de preços'!A:D, 3, FALSE), "") -> UNID | E8: =IFERROR(VLOOKUP(A8, 'Tabela de preços'!A:D, 4, FALSE), 0) -> 22.5 | F8: =C8*E8 -> 90
A9: PKT100633IN | B9: =IFERROR(VLOOKUP(A9, 'Tabela de preços'!A:D, 2, FALSE), "") -> FECHADURA SEGURANÇA 12 PINOS C/ ROLETE 70200 KESO | C9: 1 | D9: =IFERROR(VLOOKUP(A9, 'Tabela de preços'!A:D, 3, FALSE), "") -> CJ | E9: =IFERROR(VLOOKUP(A9, 'Tabela de preços'!A:D, 4, FALSE), 0) -> 1301 | F9: =C9*E9 -> 1301
A10: PKT100522IN | B10: =IFERROR(VLOOKUP(A10, 'Tabela de preços'!A:D, 2, FALSE), "") -> COLAR OBLONGO ACABAMENTO CHAVE 27,5x13mm | C10: 2 | D10: =IFERROR(VLOOKUP(A10, 'Tabela de preços'!A:D, 3, FALSE), "") -> UNID | E10: =IFERROR(VLOOKUP(A10, 'Tabela de preços'!A:D, 4, FALSE), 0) -> 40 | F10: =C10*E10 -> 80
A11: MATÉRIA PRIMA
A12: PKT100520IN | B12: =IFERROR(VLOOKUP(A12, 'Tabela de preços'!A:D, 2, FALSE), "") -> COMPENSADO NAVAL 10MM (10X1200X3000) | C12: 2 | D12: =IFERROR(VLOOKUP(A12, 'Tabela de preços'!A:D, 3, FALSE), "") -> UNID | E12: =IFERROR(VLOOKUP(A12, 'Tabela de preços'!A:D, 4, FALSE), 0) -> 185 | F12: =C12*E12 -> 370
A13: PKT-MAT-865 | B13: =IFERROR(VLOOKUP(A13, 'Tabela de preços'!A:D, 2, FALSE), "") -> LAMINA NATURAL CARVALHO EUROPEU | C13: 20 | D13: =IFERROR(VLOOKUP(A13, 'Tabela de preços'!A:D, 3, FALSE), "") -> M² | E13: =IFERROR(VLOOKUP(A13, 'Tabela de preços'!A:D, 4, FALSE), 0) -> 65 | F13: =C13*E13 -> 1300
A14: PKT400351P | B14: =IFERROR(VLOOKUP(A14, 'Tabela de preços'!A:D, 2, FALSE), "") -> MADEIRA MACIÇA TAUARI (0.02X0.30X3.00) | C14: 5 | D14: =IFERROR(VLOOKUP(A14, 'Tabela de preços'!A:D, 3, FALSE), "") -> UNID | E14: =IFERROR(VLOOKUP(A14, 'Tabela de preços'!A:D, 4, FALSE), 0) -> 52.2 | F14: =C14*E14 -> 261
A15: PKT100520IN | B15: =IFERROR(VLOOKUP(A15, 'Tabela de preços'!A:D, 2, FALSE), "") -> COMPENSADO NAVAL 10MM (10X1200X3000) | C15: 1.56 | D15: =IFERROR(VLOOKUP(A15, 'Tabela de preços'!A:D, 3, FALSE), "") -> UNID | E15: =IFERROR(VLOOKUP(A15, 'Tabela de preços'!A:D, 4, FALSE), 0) -> 185 | F15: =C15*E15 -> 288.6
A16: PKT100066IN | B16: =IFERROR(VLOOKUP(A16, 'Tabela de preços'!A:D, 2, FALSE), "") -> COLA TITE BOND 1KG | C16: 1.6 | D16: =IFERROR(VLOOKUP(A16, 'Tabela de preços'!A:D, 3, FALSE), "") -> UNID | E16: =IFERROR(VLOOKUP(A16, 'Tabela de preços'!A:D, 4, FALSE), 0) -> 50.76 | F16: =C16*E16 -> 81.216
A17: PKT100487IN | B17: =IFERROR(VLOOKUP(A17, 'Tabela de preços'!A:D, 2, FALSE), "") -> BARRA TUBO 20 X 30 X 6,00 CH PRETO | C17: 3 | D17: =IFERROR(VLOOKUP(A17, 'Tabela de preços'!A:D, 3, FALSE), "") -> BARRA | E17: =IFERROR(VLOOKUP(A17, 'Tabela de preços'!A:D, 4, FALSE), 0) -> 66.45 | F17: =C17*E17 -> 199.35
A18: PKT100064IN | B18: =IFERROR(VLOOKUP(A18, 'Tabela de preços'!A:D, 2, FALSE), "") -> FUNDO ACABAMENTO BRILHO 0 MILESSI | C18: 1 | D18: =IFERROR(VLOOKUP(A18, 'Tabela de preços'!A:D, 3, FALSE), "") -> LT | E18: =IFERROR(VLOOKUP(A18, 'Tabela de preços'!A:D, 4, FALSE), 0) -> 87.7068 | F18: =C18*E18 -> 87.7068
A19: PKT100039IN | B19: =IFERROR(VLOOKUP(A19, 'Tabela de preços'!A:D, 2, FALSE), "") -> COLA PUR TEKBOND 500G | C19: 1 | D19: =IFERROR(VLOOKUP(A19, 'Tabela de preços'!A:D, 3, FALSE), "") -> UNID | E19: =IFERROR(VLOOKUP(A19, 'Tabela de preços'!A:D, 4, FALSE), 0) -> 33.64 | F19: =C19*E19 -> 33.64
A20: PKT100504IN | B20: =IFERROR(VLOOKUP(A20, 'Tabela de preços'!A:D, 2, FALSE), "") -> GRAMPO TIPO ''U'' 80x12MM | C20: 1 | D20: =IFERROR(VLOOKUP(A20, 'Tabela de preços'!A:D, 3, FALSE), "") -> CT | E20: =IFERROR(VLOOKUP(A20, 'Tabela de preços'!A:D, 4, FALSE), 0) -> 2 | F20: =C20*E20 -> 2
A21: PKT100218IN | B21: =IFERROR(VLOOKUP(A21, 'Tabela de preços'!A:D, 2, FALSE), "") -> PINO F30 P/ PINADOR PNEUMATICO | C21: 1 | D21: =IFERROR(VLOOKUP(A21, 'Tabela de preços'!A:D, 3, FALSE), "") -> CT | E21: =IFERROR(VLOOKUP(A21, 'Tabela de preços'!A:D, 4, FALSE), 0) -> 0.452 | F21: =C21*E21 -> 0.452
A22: INSUMOS DE OBRA
A23: PKT100521IN | B23: =IFERROR(VLOOKUP(A23, 'Tabela de preços'!A:D, 2, FALSE), "") -> PARAFUSO BICROMATIZADO PHILIPS 6.0X80MM | C23: 0.2 | D23: =IFERROR(VLOOKUP(A23, 'Tabela de preços'!A:D, 3, FALSE), "") -> CT | E23: =IFERROR(VLOOKUP(A23, 'Tabela de preços'!A:D, 4, FALSE), 0) -> 28 | F23: =C23*E23 -> 5.6
A24: PKT100024IN | B24: =IFERROR(VLOOKUP(A24, 'Tabela de preços'!A:D, 2, FALSE), "") -> BUCHA 08MM | C24: 0.2 | D24: =IFERROR(VLOOKUP(A24, 'Tabela de preços'!A:D, 3, FALSE), "") -> CT | E24: =IFERROR(VLOOKUP(A24, 'Tabela de preços'!A:D, 4, FALSE), 0) -> 18 | F24: =C24*E24 -> 3.6
E26: CUSTO TOTAL DA PORTA: | F26: =SUM(F5:F24) -> 4454.4748

Sheet PT PIVO ITALY LINE INT
A1: COMPOSIÇÃO DE CUSTOS - PT PIVO ITALY LINE INT
A2: Estrutura de custos por item integrada dinamicamente à Tabela de Preços
A4: CÓDIGO ITEM | B4: DESCRIÇÃO DO ITEM | C4: QUANTIDADE | D4: UNID MEDIDA | E4: CUSTO UNITÁRIO (R$) | F4: CUSTO TOTAL (R$)
A5: FERRAGENS
A6: PKT100297IN | B6: =IFERROR(VLOOKUP(A6, 'Tabela de preços'!A:D, 2, FALSE), "") -> PIVOT IL 100 (INVISIVEL) 280KG - ITALY LINE | C6: 1 | D6: =IFERROR(VLOOKUP(A6, 'Tabela de preços'!A:D, 3, FALSE), "") -> UNID | E6: =IFERROR(VLOOKUP(A6, 'Tabela de preços'!A:D, 4, FALSE), 0) -> 331.8 | F6: =C6*E6 -> 331.8
A7: PKT100050IN | B7: =IFERROR(VLOOKUP(A7, 'Tabela de preços'!A:D, 2, FALSE), "") -> VEDA FRESTAS 04 X 09MM MARROM CLARO C/ 06 MT | C7: 1 | D7: =IFERROR(VLOOKUP(A7, 'Tabela de preços'!A:D, 3, FALSE), "") -> UNID | E7: =IFERROR(VLOOKUP(A7, 'Tabela de preços'!A:D, 4, FALSE), 0) -> 18.51 | F7: =C7*E7 -> 18.51
A8: PKT100070IN | B8: =IFERROR(VLOOKUP(A8, 'Tabela de preços'!A:D, 2, FALSE), "") -> IMÃ 22X10 N.42 | C8: 4 | D8: =IFERROR(VLOOKUP(A8, 'Tabela de preços'!A:D, 3, FALSE), "") -> UNID | E8: =IFERROR(VLOOKUP(A8, 'Tabela de preços'!A:D, 4, FALSE), 0) -> 22.5 | F8: =C8*E8 -> 90
A9: PKT100505IN | B9: =IFERROR(VLOOKUP(A9, 'Tabela de preços'!A:D, 2, FALSE), "") -> FECHADURA AUX LINGUETA RETA INOX FOSCO 911.22.490 | C9: 1 | D9: =IFERROR(VLOOKUP(A9, 'Tabela de preços'!A:D, 3, FALSE), "") -> UNID | E9: =IFERROR(VLOOKUP(A9, 'Tabela de preços'!A:D, 4, FALSE), 0) -> 105.204 | F9: =C9*E9 -> 105.204
A10: PKT100519IN | B10: =IFERROR(VLOOKUP(A10, 'Tabela de preços'!A:D, 2, FALSE), "") -> ADAPTADOR INTERNO, PARA FECHADURAS COD 911.03.886 | C10: 1 | D10: =IFERROR(VLOOKUP(A10, 'Tabela de preços'!A:D, 3, FALSE), "") -> UNID | E10: =IFERROR(VLOOKUP(A10, 'Tabela de preços'!A:D, 4, FALSE), 0) -> 33.26 | F10: =C10*E10 -> 33.26
A11: PKT100522IN | B11: =IFERROR(VLOOKUP(A11, 'Tabela de preços'!A:D, 2, FALSE), "") -> COLAR OBLONGO ACABAMENTO CHAVE 27,5x13mm | C11: 2 | D11: =IFERROR(VLOOKUP(A11, 'Tabela de preços'!A:D, 3, FALSE), "") -> UNID | E11: =IFERROR(VLOOKUP(A11, 'Tabela de preços'!A:D, 4, FALSE), 0) -> 40 | F11: =C11*E11 -> 80
A12: MATÉRIA PRIMA
A13: PKT100520IN | B13: =IFERROR(VLOOKUP(A13, 'Tabela de preços'!A:D, 2, FALSE), "") -> COMPENSADO NAVAL 10MM (10X1200X3000) | C13: 2 | D13: =IFERROR(VLOOKUP(A13, 'Tabela de preços'!A:D, 3, FALSE), "") -> UNID | E13: =IFERROR(VLOOKUP(A13, 'Tabela de preços'!A:D, 4, FALSE), 0) -> 185 | F13: =C13*E13 -> 370
A14: PKT-MAT-865 | B14: =IFERROR(VLOOKUP(A14, 'Tabela de preços'!A:D, 2, FALSE), "") -> LAMINA NATURAL CARVALHO EUROPEU | C14: 20 | D14: =IFERROR(VLOOKUP(A14, 'Tabela de preços'!A:D, 3, FALSE), "") -> M² | E14: =IFERROR(VLOOKUP(A14, 'Tabela de preços'!A:D, 4, FALSE), 0) -> 65 | F14: =C14*E14 -> 1300
A15: PKT400351P | B15: =IFERROR(VLOOKUP(A15, 'Tabela de preços'!A:D, 2, FALSE), "") -> MADEIRA MACIÇA TAUARI (0.02X0.30X3.00) | C15: 5 | D15: =IFERROR(VLOOKUP(A15, 'Tabela de preços'!A:D, 3, FALSE), "") -> UNID | E15: =IFERROR(VLOOKUP(A15, 'Tabela de preços'!A:D, 4, FALSE), 0) -> 52.2 | F15: =C15*E15 -> 261
A16: PKT100520IN | B16: =IFERROR(VLOOKUP(A16, 'Tabela de preços'!A:D, 2, FALSE), "") -> COMPENSADO NAVAL 10MM (10X1200X3000) | C16: 1.56 | D16: =IFERROR(VLOOKUP(A16, 'Tabela de preços'!A:D, 3, FALSE), "") -> UNID | E16: =IFERROR(VLOOKUP(A16, 'Tabela de preços'!A:D, 4, FALSE), 0) -> 185 | F16: =C16*E16 -> 288.6
A17: PKT100066IN | B17: =IFERROR(VLOOKUP(A17, 'Tabela de preços'!A:D, 2, FALSE), "") -> COLA TITE BOND 1KG | C17: 1.6 | D17: =IFERROR(VLOOKUP(A17, 'Tabela de preços'!A:D, 3, FALSE), "") -> UNID | E17: =IFERROR(VLOOKUP(A17, 'Tabela de preços'!A:D, 4, FALSE), 0) -> 50.76 | F17: =C17*E17 -> 81.216
A18: PKT100487IN | B18: =IFERROR(VLOOKUP(A18, 'Tabela de preços'!A:D, 2, FALSE), "") -> BARRA TUBO 20 X 30 X 6,00 CH PRETO | C18: 3 | D18: =IFERROR(VLOOKUP(A18, 'Tabela de preços'!A:D, 3, FALSE), "") -> BARRA | E18: =IFERROR(VLOOKUP(A18, 'Tabela de preços'!A:D, 4, FALSE), 0) -> 66.45 | F18: =C18*E18 -> 199.35
A19: PKT100064IN | B19: =IFERROR(VLOOKUP(A19, 'Tabela de preços'!A:D, 2, FALSE), "") -> FUNDO ACABAMENTO BRILHO 0 MILESSI | C19: 1 | D19: =IFERROR(VLOOKUP(A19, 'Tabela de preços'!A:D, 3, FALSE), "") -> LT | E19: =IFERROR(VLOOKUP(A19, 'Tabela de preços'!A:D, 4, FALSE), 0) -> 87.7068 | F19: =C19*E19 -> 87.7068
A20: PKT100039IN | B20: =IFERROR(VLOOKUP(A20, 'Tabela de preços'!A:D, 2, FALSE), "") -> COLA PUR TEKBOND 500G | C20: 1 | D20: =IFERROR(VLOOKUP(A20, 'Tabela de preços'!A:D, 3, FALSE), "") -> UNID | E20: =IFERROR(VLOOKUP(A20, 'Tabela de preços'!A:D, 4, FALSE), 0) -> 33.64 | F20: =C20*E20 -> 33.64
A21: PKT100504IN | B21: =IFERROR(VLOOKUP(A21, 'Tabela de preços'!A:D, 2, FALSE), "") -> GRAMPO TIPO ''U'' 80x12MM | C21: 1 | D21: =IFERROR(VLOOKUP(A21, 'Tabela de preços'!A:D, 3, FALSE), "") -> CT | E21: =IFERROR(VLOOKUP(A21, 'Tabela de preços'!A:D, 4, FALSE), 0) -> 2 | F21: =C21*E21 -> 2
A22: PKT100218IN | B22: =IFERROR(VLOOKUP(A22, 'Tabela de preços'!A:D, 2, FALSE), "") -> PINO F30 P/ PINADOR PNEUMATICO | C22: 1 | D22: =IFERROR(VLOOKUP(A22, 'Tabela de preços'!A:D, 3, FALSE), "") -> CT | E22: =IFERROR(VLOOKUP(A22, 'Tabela de preços'!A:D, 4, FALSE), 0) -> 0.452 | F22: =C22*E22 -> 0.452
A23: INSUMOS DE OBRA
A24: PKT100521IN | B24: =IFERROR(VLOOKUP(A24, 'Tabela de preços'!A:D, 2, FALSE), "") -> PARAFUSO BICROMATIZADO PHILIPS 6.0X80MM | C24: 0.2 | D24: =IFERROR(VLOOKUP(A24, 'Tabela de preços'!A:D, 3, FALSE), "") -> CT | E24: =IFERROR(VLOOKUP(A24, 'Tabela de preços'!A:D, 4, FALSE), 0) -> 28 | F24: =C24*E24 -> 5.6
A25: PKT100024IN | B25: =IFERROR(VLOOKUP(A25, 'Tabela de preços'!A:D, 2, FALSE), "") -> BUCHA 08MM | C25: 0.2 | D25: =IFERROR(VLOOKUP(A25, 'Tabela de preços'!A:D, 3, FALSE), "") -> CT | E25: =IFERROR(VLOOKUP(A25, 'Tabela de preços'!A:D, 4, FALSE), 0) -> 18 | F25: =C25*E25 -> 3.6
E27: CUSTO TOTAL DA PORTA: | F27: =SUM(F5:F25) -> 3291.9388

Sheet PT PIVO ITALYNE WC
A1: COMPOSIÇÃO DE CUSTOS - PT PIVO ITALYNE WC
A2: Estrutura de custos por item integrada dinamicamente à Tabela de Preços
A4: CÓDIGO ITEM | B4: DESCRIÇÃO DO ITEM | C4: QUANTIDADE | D4: UNID MEDIDA | E4: CUSTO UNITÁRIO (R$) | F4: CUSTO TOTAL (R$)
A5: FERRAGENS
A6: PKT100297IN | B6: =IFERROR(VLOOKUP(A6, 'Tabela de preços'!A:D, 2, FALSE), "") -> PIVOT IL 100 (INVISIVEL) 280KG - ITALY LINE | C6: 1 | D6: =IFERROR(VLOOKUP(A6, 'Tabela de preços'!A:D, 3, FALSE), "") -> UNID | E6: =IFERROR(VLOOKUP(A6, 'Tabela de preços'!A:D, 4, FALSE), 0) -> 331.8 | F6: =C6*E6 -> 331.8
A7: PKT100050IN | B7: =IFERROR(VLOOKUP(A7, 'Tabela de preços'!A:D, 2, FALSE), "") -> VEDA FRESTAS 04 X 09MM MARROM CLARO C/ 06 MT | C7: 1 | D7: =IFERROR(VLOOKUP(A7, 'Tabela de preços'!A:D, 3, FALSE), "") -> UNID | E7: =IFERROR(VLOOKUP(A7, 'Tabela de preços'!A:D, 4, FALSE), 0) -> 18.51 | F7: =C7*E7 -> 18.51
A8: PKT100070IN | B8: =IFERROR(VLOOKUP(A8, 'Tabela de preços'!A:D, 2, FALSE), "") -> IMÃ 22X10 N.42 | C8: 4 | D8: =IFERROR(VLOOKUP(A8, 'Tabela de preços'!A:D, 3, FALSE), "") -> UNID | E8: =IFERROR(VLOOKUP(A8, 'Tabela de preços'!A:D, 4, FALSE), 0) -> 22.5 | F8: =C8*E8 -> 90
A9: PKT100505IN | B9: =IFERROR(VLOOKUP(A9, 'Tabela de preços'!A:D, 2, FALSE), "") -> FECHADURA AUX LINGUETA RETA INOX FOSCO 911.22.490 | C9: 1 | D9: =IFERROR(VLOOKUP(A9, 'Tabela de preços'!A:D, 3, FALSE), "") -> UNID | E9: =IFERROR(VLOOKUP(A9, 'Tabela de preços'!A:D, 4, FALSE), 0) -> 105.204 | F9: =C9*E9 -> 105.204
A10: PKT100506IN | B10: =IFERROR(VLOOKUP(A10, 'Tabela de preços'!A:D, 2, FALSE), "") -> ADAPTADOR P/WC ZMK NIQ 911.03.885 | C10: 1 | D10: =IFERROR(VLOOKUP(A10, 'Tabela de preços'!A:D, 3, FALSE), "") -> UNID | E10: =IFERROR(VLOOKUP(A10, 'Tabela de preços'!A:D, 4, FALSE), 0) -> 19.12 | F10: =C10*E10 -> 19.12
A11: PKT100512IN | B11: =IFERROR(VLOOKUP(A11, 'Tabela de preços'!A:D, 2, FALSE), "") -> TRANQUETA GOTINHA AÇO INOX ESCOVADO | C11: 1 | D11: =IFERROR(VLOOKUP(A11, 'Tabela de preços'!A:D, 3, FALSE), "") -> UNID | E11: =IFERROR(VLOOKUP(A11, 'Tabela de preços'!A:D, 4, FALSE), 0) -> 293 | F11: =C11*E11 -> 293
A12: MATÉRIA PRIMA
A13: PKT100520IN | B13: =IFERROR(VLOOKUP(A13, 'Tabela de preços'!A:D, 2, FALSE), "") -> COMPENSADO NAVAL 10MM (10X1200X3000) | C13: 2 | D13: =IFERROR(VLOOKUP(A13, 'Tabela de preços'!A:D, 3, FALSE), "") -> UNID | E13: =IFERROR(VLOOKUP(A13, 'Tabela de preços'!A:D, 4, FALSE), 0) -> 185 | F13: =C13*E13 -> 370
A14: PKT-MAT-865 | B14: =IFERROR(VLOOKUP(A14, 'Tabela de preços'!A:D, 2, FALSE), "") -> LAMINA NATURAL CARVALHO EUROPEU | C14: 20 | D14: =IFERROR(VLOOKUP(A14, 'Tabela de preços'!A:D, 3, FALSE), "") -> M² | E14: =IFERROR(VLOOKUP(A14, 'Tabela de preços'!A:D, 4, FALSE), 0) -> 65 | F14: =C14*E14 -> 1300
A15: PKT400351P | B15: =IFERROR(VLOOKUP(A15, 'Tabela de preços'!A:D, 2, FALSE), "") -> MADEIRA MACIÇA TAUARI (0.02X0.30X3.00) | C15: 5 | D15: =IFERROR(VLOOKUP(A15, 'Tabela de preços'!A:D, 3, FALSE), "") -> UNID | E15: =IFERROR(VLOOKUP(A15, 'Tabela de preços'!A:D, 4, FALSE), 0) -> 52.2 | F15: =C15*E15 -> 261
A16: PKT100520IN | B16: =IFERROR(VLOOKUP(A16, 'Tabela de preços'!A:D, 2, FALSE), "") -> COMPENSADO NAVAL 10MM (10X1200X3000) | C16: 1.56 | D16: =IFERROR(VLOOKUP(A16, 'Tabela de preços'!A:D, 3, FALSE), "") -> UNID | E16: =IFERROR(VLOOKUP(A16, 'Tabela de preços'!A:D, 4, FALSE), 0) -> 185 | F16: =C16*E16 -> 288.6
A17: PKT100066IN | B17: =IFERROR(VLOOKUP(A17, 'Tabela de preços'!A:D, 2, FALSE), "") -> COLA TITE BOND 1KG | C17: 1.6 | D17: =IFERROR(VLOOKUP(A17, 'Tabela de preços'!A:D, 3, FALSE), "") -> UNID | E17: =IFERROR(VLOOKUP(A17, 'Tabela de preços'!A:D, 4, FALSE), 0) -> 50.76 | F17: =C17*E17 -> 81.216
A18: PKT100487IN | B18: =IFERROR(VLOOKUP(A18, 'Tabela de preços'!A:D, 2, FALSE), "") -> BARRA TUBO 20 X 30 X 6,00 CH PRETO | C18: 3 | D18: =IFERROR(VLOOKUP(A18, 'Tabela de preços'!A:D, 3, FALSE), "") -> BARRA | E18: =IFERROR(VLOOKUP(A18, 'Tabela de preços'!A:D, 4, FALSE), 0) -> 66.45 | F18: =C18*E18 -> 199.35
A19: PKT100064IN | B19: =IFERROR(VLOOKUP(A19, 'Tabela de preços'!A:D, 2, FALSE), "") -> FUNDO ACABAMENTO BRILHO 0 MILESSI | C19: 1 | D19: =IFERROR(VLOOKUP(A19, 'Tabela de preços'!A:D, 3, FALSE), "") -> LT | E19: =IFERROR(VLOOKUP(A19, 'Tabela de preços'!A:D, 4, FALSE), 0) -> 87.7068 | F19: =C19*E19 -> 87.7068
A20: PKT100039IN | B20: =IFERROR(VLOOKUP(A20, 'Tabela de preços'!A:D, 2, FALSE), "") -> COLA PUR TEKBOND 500G | C20: 1 | D20: =IFERROR(VLOOKUP(A20, 'Tabela de preços'!A:D, 3, FALSE), "") -> UNID | E20: =IFERROR(VLOOKUP(A20, 'Tabela de preços'!A:D, 4, FALSE), 0) -> 33.64 | F20: =C20*E20 -> 33.64
A21: PKT100504IN | B21: =IFERROR(VLOOKUP(A21, 'Tabela de preços'!A:D, 2, FALSE), "") -> GRAMPO TIPO ''U'' 80x12MM | C21: 1 | D21: =IFERROR(VLOOKUP(A21, 'Tabela de preços'!A:D, 3, FALSE), "") -> CT | E21: =IFERROR(VLOOKUP(A21, 'Tabela de preços'!A:D, 4, FALSE), 0) -> 2 | F21: =C21*E21 -> 2
A22: PKT100218IN | B22: =IFERROR(VLOOKUP(A22, 'Tabela de preços'!A:D, 2, FALSE), "") -> PINO F30 P/ PINADOR PNEUMATICO | C22: 1 | D22: =IFERROR(VLOOKUP(A22, 'Tabela de preços'!A:D, 3, FALSE), "") -> CT | E22: =IFERROR(VLOOKUP(A22, 'Tabela de preços'!A:D, 4, FALSE), 0) -> 0.452 | F22: =C22*E22 -> 0.452
A23: INSUMOS DE OBRA
A24: PKT100521IN | B24: =IFERROR(VLOOKUP(A24, 'Tabela de preços'!A:D, 2, FALSE), "") -> PARAFUSO BICROMATIZADO PHILIPS 6.0X80MM | C24: 0.2 | D24: =IFERROR(VLOOKUP(A24, 'Tabela de preços'!A:D, 3, FALSE), "") -> CT | E24: =IFERROR(VLOOKUP(A24, 'Tabela de preços'!A:D, 4, FALSE), 0) -> 28 | F24: =C24*E24 -> 5.6
A25: PKT100024IN | B25: =IFERROR(VLOOKUP(A25, 'Tabela de preços'!A:D, 2, FALSE), "") -> BUCHA 08MM | C25: 0.2 | D25: =IFERROR(VLOOKUP(A25, 'Tabela de preços'!A:D, 3, FALSE), "") -> CT | E25: =IFERROR(VLOOKUP(A25, 'Tabela de preços'!A:D, 4, FALSE), 0) -> 18 | F25: =C25*E25 -> 3.6
E27: CUSTO TOTAL DA PORTA: | F27: =SUM(F5:F25) -> 3490.7988

Sheet PT PIVO CIR INTERNA
A1: COMPOSIÇÃO DE CUSTOS - PT PIVO CIR INTERNA
A2: Estrutura de custos por item integrada dinamicamente à Tabela de Preços
A4: CÓDIGO ITEM | B4: DESCRIÇÃO DO ITEM | C4: QUANTIDADE | D4: UNID MEDIDA | E4: CUSTO UNITÁRIO (R$) | F4: CUSTO TOTAL (R$)
A5: FERRAGENS
A6: PKT100511IN | B6: =IFERROR(VLOOKUP(A6, 'Tabela de preços'!A:D, 2, FALSE), "") -> PIVÔ CIR 80KG - ECLISSE | C6: 1 | D6: =IFERROR(VLOOKUP(A6, 'Tabela de preços'!A:D, 3, FALSE), "") -> UNID | E6: =IFERROR(VLOOKUP(A6, 'Tabela de preços'!A:D, 4, FALSE), 0) -> 463.025 | F6: =C6*E6 -> 463.025
A7: PKT100050IN | B7: =IFERROR(VLOOKUP(A7, 'Tabela de preços'!A:D, 2, FALSE), "") -> VEDA FRESTAS 04 X 09MM MARROM CLARO C/ 06 MT | C7: 1 | D7: =IFERROR(VLOOKUP(A7, 'Tabela de preços'!A:D, 3, FALSE), "") -> UNID | E7: =IFERROR(VLOOKUP(A7, 'Tabela de preços'!A:D, 4, FALSE), 0) -> 18.51 | F7: =C7*E7 -> 18.51
A8: PKT100070IN | B8: =IFERROR(VLOOKUP(A8, 'Tabela de preços'!A:D, 2, FALSE), "") -> IMÃ 22X10 N.42 | C8: 4 | D8: =IFERROR(VLOOKUP(A8, 'Tabela de preços'!A:D, 3, FALSE), "") -> UNID | E8: =IFERROR(VLOOKUP(A8, 'Tabela de preços'!A:D, 4, FALSE), 0) -> 22.5 | F8: =C8*E8 -> 90
A9: PKT100505IN | B9: =IFERROR(VLOOKUP(A9, 'Tabela de preços'!A:D, 2, FALSE), "") -> FECHADURA AUX LINGUETA RETA INOX FOSCO 911.22.490 | C9: 1 | D9: =IFERROR(VLOOKUP(A9, 'Tabela de preços'!A:D, 3, FALSE), "") -> UNID | E9: =IFERROR(VLOOKUP(A9, 'Tabela de preços'!A:D, 4, FALSE), 0) -> 105.204 | F9: =C9*E9 -> 105.204
A10: PKT100519IN | B10: =IFERROR(VLOOKUP(A10, 'Tabela de preços'!A:D, 2, FALSE), "") -> ADAPTADOR INTERNO, PARA FECHADURAS COD 911.03.886 | C10: 1 | D10: =IFERROR(VLOOKUP(A10, 'Tabela de preços'!A:D, 3, FALSE), "") -> UNID | E10: =IFERROR(VLOOKUP(A10, 'Tabela de preços'!A:D, 4, FALSE), 0) -> 33.26 | F10: =C10*E10 -> 33.26
A11: PKT100522IN | B11: =IFERROR(VLOOKUP(A11, 'Tabela de preços'!A:D, 2, FALSE), "") -> COLAR OBLONGO ACABAMENTO CHAVE 27,5x13mm | C11: 2 | D11: =IFERROR(VLOOKUP(A11, 'Tabela de preços'!A:D, 3, FALSE), "") -> UNID | E11: =IFERROR(VLOOKUP(A11, 'Tabela de preços'!A:D, 4, FALSE), 0) -> 40 | F11: =C11*E11 -> 80
A12: MATÉRIA PRIMA
A13: PKT100520IN | B13: =IFERROR(VLOOKUP(A13, 'Tabela de preços'!A:D, 2, FALSE), "") -> COMPENSADO NAVAL 10MM (10X1200X3000) | C13: 2 | D13: =IFERROR(VLOOKUP(A13, 'Tabela de preços'!A:D, 3, FALSE), "") -> UNID | E13: =IFERROR(VLOOKUP(A13, 'Tabela de preços'!A:D, 4, FALSE), 0) -> 185 | F13: =C13*E13 -> 370
A14: PKT-MAT-865 | B14: =IFERROR(VLOOKUP(A14, 'Tabela de preços'!A:D, 2, FALSE), "") -> LAMINA NATURAL CARVALHO EUROPEU | C14: 20 | D14: =IFERROR(VLOOKUP(A14, 'Tabela de preços'!A:D, 3, FALSE), "") -> M² | E14: =IFERROR(VLOOKUP(A14, 'Tabela de preços'!A:D, 4, FALSE), 0) -> 65 | F14: =C14*E14 -> 1300
A15: PKT400351P | B15: =IFERROR(VLOOKUP(A15, 'Tabela de preços'!A:D, 2, FALSE), "") -> MADEIRA MACIÇA TAUARI (0.02X0.30X3.00) | C15: 5 | D15: =IFERROR(VLOOKUP(A15, 'Tabela de preços'!A:D, 3, FALSE), "") -> UNID | E15: =IFERROR(VLOOKUP(A15, 'Tabela de preços'!A:D, 4, FALSE), 0) -> 52.2 | F15: =C15*E15 -> 261
A16: PKT100520IN | B16: =IFERROR(VLOOKUP(A16, 'Tabela de preços'!A:D, 2, FALSE), "") -> COMPENSADO NAVAL 10MM (10X1200X3000) | C16: 1.56 | D16: =IFERROR(VLOOKUP(A16, 'Tabela de preços'!A:D, 3, FALSE), "") -> UNID | E16: =IFERROR(VLOOKUP(A16, 'Tabela de preços'!A:D, 4, FALSE), 0) -> 185 | F16: =C16*E16 -> 288.6
A17: PKT100066IN | B17: =IFERROR(VLOOKUP(A17, 'Tabela de preços'!A:D, 2, FALSE), "") -> COLA TITE BOND 1KG | C17: 1.6 | D17: =IFERROR(VLOOKUP(A17, 'Tabela de preços'!A:D, 3, FALSE), "") -> UNID | E17: =IFERROR(VLOOKUP(A17, 'Tabela de preços'!A:D, 4, FALSE), 0) -> 50.76 | F17: =C17*E17 -> 81.216
A18: PKT100487IN | B18: =IFERROR(VLOOKUP(A18, 'Tabela de preços'!A:D, 2, FALSE), "") -> BARRA TUBO 20 X 30 X 6,00 CH PRETO | C18: 3 | D18: =IFERROR(VLOOKUP(A18, 'Tabela de preços'!A:D, 3, FALSE), "") -> BARRA | E18: =IFERROR(VLOOKUP(A18, 'Tabela de preços'!A:D, 4, FALSE), 0) -> 66.45 | F18: =C18*E18 -> 199.35
A19: PKT100064IN | B19: =IFERROR(VLOOKUP(A19, 'Tabela de preços'!A:D, 2, FALSE), "") -> FUNDO ACABAMENTO BRILHO 0 MILESSI | C19: 1 | D19: =IFERROR(VLOOKUP(A19, 'Tabela de preços'!A:D, 3, FALSE), "") -> LT | E19: =IFERROR(VLOOKUP(A19, 'Tabela de preços'!A:D, 4, FALSE), 0) -> 87.7068 | F19: =C19*E19 -> 87.7068
A20: PKT100039IN | B20: =IFERROR(VLOOKUP(A20, 'Tabela de preços'!A:D, 2, FALSE), "") -> COLA PUR TEKBOND 500G | C20: 1 | D20: =IFERROR(VLOOKUP(A20, 'Tabela de preços'!A:D, 3, FALSE), "") -> UNID | E20: =IFERROR(VLOOKUP(A20, 'Tabela de preços'!A:D, 4, FALSE), 0) -> 33.64 | F20: =C20*E20 -> 33.64
A21: PKT100504IN | B21: =IFERROR(VLOOKUP(A21, 'Tabela de preços'!A:D, 2, FALSE), "") -> GRAMPO TIPO ''U'' 80x12MM | C21: 1 | D21: =IFERROR(VLOOKUP(A21, 'Tabela de preços'!A:D, 3, FALSE), "") -> CT | E21: =IFERROR(VLOOKUP(A21, 'Tabela de preços'!A:D, 4, FALSE), 0) -> 2 | F21: =C21*E21 -> 2
A22: PKT100218IN | B22: =IFERROR(VLOOKUP(A22, 'Tabela de preços'!A:D, 2, FALSE), "") -> PINO F30 P/ PINADOR PNEUMATICO | C22: 1 | D22: =IFERROR(VLOOKUP(A22, 'Tabela de preços'!A:D, 3, FALSE), "") -> CT | E22: =IFERROR(VLOOKUP(A22, 'Tabela de preços'!A:D, 4, FALSE), 0) -> 0.452 | F22: =C22*E22 -> 0.452
A23: INSUMOS DE OBRA
A24: PKT100521IN | B24: =IFERROR(VLOOKUP(A24, 'Tabela de preços'!A:D, 2, FALSE), "") -> PARAFUSO BICROMATIZADO PHILIPS 6.0X80MM | C24: 0.2 | D24: =IFERROR(VLOOKUP(A24, 'Tabela de preços'!A:D, 3, FALSE), "") -> CT | E24: =IFERROR(VLOOKUP(A24, 'Tabela de preços'!A:D, 4, FALSE), 0) -> 28 | F24: =C24*E24 -> 5.6
A25: PKT100024IN | B25: =IFERROR(VLOOKUP(A25, 'Tabela de preços'!A:D, 2, FALSE), "") -> BUCHA 08MM | C25: 0.2 | D25: =IFERROR(VLOOKUP(A25, 'Tabela de preços'!A:D, 3, FALSE), "") -> CT | E25: =IFERROR(VLOOKUP(A25, 'Tabela de preços'!A:D, 4, FALSE), 0) -> 18 | F25: =C25*E25 -> 3.6
E27: CUSTO TOTAL DA PORTA: | F27: =SUM(F5:F25) -> 3423.1638

Sheet PT PIVO CIR WC
A1: COMPOSIÇÃO DE CUSTOS - PT PIVO CIR WC
A2: Estrutura de custos por item integrada dinamicamente à Tabela de Preços
A4: CÓDIGO ITEM | B4: DESCRIÇÃO DO ITEM | C4: QUANTIDADE | D4: UNID MEDIDA | E4: CUSTO UNITÁRIO (R$) | F4: CUSTO TOTAL (R$)
A5: FERRAGENS
A6: PKT100511IN | B6: =IFERROR(VLOOKUP(A6, 'Tabela de preços'!A:D, 2, FALSE), "") -> PIVÔ CIR 80KG - ECLISSE | C6: 1 | D6: =IFERROR(VLOOKUP(A6, 'Tabela de preços'!A:D, 3, FALSE), "") -> UNID | E6: =IFERROR(VLOOKUP(A6, 'Tabela de preços'!A:D, 4, FALSE), 0) -> 463.025 | F6: =C6*E6 -> 463.025
A7: PKT100050IN | B7: =IFERROR(VLOOKUP(A7, 'Tabela de preços'!A:D, 2, FALSE), "") -> VEDA FRESTAS 04 X 09MM MARROM CLARO C/ 06 MT | C7: 1 | D7: =IFERROR(VLOOKUP(A7, 'Tabela de preços'!A:D, 3, FALSE), "") -> UNID | E7: =IFERROR(VLOOKUP(A7, 'Tabela de preços'!A:D, 4, FALSE), 0) -> 18.51 | F7: =C7*E7 -> 18.51
A8: PKT100070IN | B8: =IFERROR(VLOOKUP(A8, 'Tabela de preços'!A:D, 2, FALSE), "") -> IMÃ 22X10 N.42 | C8: 4 | D8: =IFERROR(VLOOKUP(A8, 'Tabela de preços'!A:D, 3, FALSE), "") -> UNID | E8: =IFERROR(VLOOKUP(A8, 'Tabela de preços'!A:D, 4, FALSE), 0) -> 22.5 | F8: =C8*E8 -> 90
A9: PKT100505IN | B9: =IFERROR(VLOOKUP(A9, 'Tabela de preços'!A:D, 2, FALSE), "") -> FECHADURA AUX LINGUETA RETA INOX FOSCO 911.22.490 | C9: 1 | D9: =IFERROR(VLOOKUP(A9, 'Tabela de preços'!A:D, 3, FALSE), "") -> UNID | E9: =IFERROR(VLOOKUP(A9, 'Tabela de preços'!A:D, 4, FALSE), 0) -> 105.204 | F9: =C9*E9 -> 105.204
A10: PKT100506IN | B10: =IFERROR(VLOOKUP(A10, 'Tabela de preços'!A:D, 2, FALSE), "") -> ADAPTADOR P/WC ZMK NIQ 911.03.885 | C10: 1 | D10: =IFERROR(VLOOKUP(A10, 'Tabela de preços'!A:D, 3, FALSE), "") -> UNID | E10: =IFERROR(VLOOKUP(A10, 'Tabela de preços'!A:D, 4, FALSE), 0) -> 19.12 | F10: =C10*E10 -> 19.12
A11: PKT100512IN | B11: =IFERROR(VLOOKUP(A11, 'Tabela de preços'!A:D, 2, FALSE), "") -> TRANQUETA GOTINHA AÇO INOX ESCOVADO | C11: 1 | D11: =IFERROR(VLOOKUP(A11, 'Tabela de preços'!A:D, 3, FALSE), "") -> UNID | E11: =IFERROR(VLOOKUP(A11, 'Tabela de preços'!A:D, 4, FALSE), 0) -> 293 | F11: =C11*E11 -> 293
A12: MATÉRIA PRIMA
A13: PKT100520IN | B13: =IFERROR(VLOOKUP(A13, 'Tabela de preços'!A:D, 2, FALSE), "") -> COMPENSADO NAVAL 10MM (10X1200X3000) | C13: 2 | D13: =IFERROR(VLOOKUP(A13, 'Tabela de preços'!A:D, 3, FALSE), "") -> UNID | E13: =IFERROR(VLOOKUP(A13, 'Tabela de preços'!A:D, 4, FALSE), 0) -> 185 | F13: =C13*E13 -> 370
A14: PKT-MAT-865 | B14: =IFERROR(VLOOKUP(A14, 'Tabela de preços'!A:D, 2, FALSE), "") -> LAMINA NATURAL CARVALHO EUROPEU | C14: 20 | D14: =IFERROR(VLOOKUP(A14, 'Tabela de preços'!A:D, 3, FALSE), "") -> M² | E14: =IFERROR(VLOOKUP(A14, 'Tabela de preços'!A:D, 4, FALSE), 0) -> 65 | F14: =C14*E14 -> 1300
A15: PKT400351P | B15: =IFERROR(VLOOKUP(A15, 'Tabela de preços'!A:D, 2, FALSE), "") -> MADEIRA MACIÇA TAUARI (0.02X0.30X3.00) | C15: 5 | D15: =IFERROR(VLOOKUP(A15, 'Tabela de preços'!A:D, 3, FALSE), "") -> UNID | E15: =IFERROR(VLOOKUP(A15, 'Tabela de preços'!A:D, 4, FALSE), 0) -> 52.2 | F15: =C15*E15 -> 261
A16: PKT100520IN | B16: =IFERROR(VLOOKUP(A16, 'Tabela de preços'!A:D, 2, FALSE), "") -> COMPENSADO NAVAL 10MM (10X1200X3000) | C16: 1.56 | D16: =IFERROR(VLOOKUP(A16, 'Tabela de preços'!A:D, 3, FALSE), "") -> UNID | E16: =IFERROR(VLOOKUP(A16, 'Tabela de preços'!A:D, 4, FALSE), 0) -> 185 | F16: =C16*E16 -> 288.6
A17: PKT100066IN | B17: =IFERROR(VLOOKUP(A17, 'Tabela de preços'!A:D, 2, FALSE), "") -> COLA TITE BOND 1KG | C17: 1.6 | D17: =IFERROR(VLOOKUP(A17, 'Tabela de preços'!A:D, 3, FALSE), "") -> UNID | E17: =IFERROR(VLOOKUP(A17, 'Tabela de preços'!A:D, 4, FALSE), 0) -> 50.76 | F17: =C17*E17 -> 81.216
A18: PKT100487IN | B18: =IFERROR(VLOOKUP(A18, 'Tabela de preços'!A:D, 2, FALSE), "") -> BARRA TUBO 20 X 30 X 6,00 CH PRETO | C18: 3 | D18: =IFERROR(VLOOKUP(A18, 'Tabela de preços'!A:D, 3, FALSE), "") -> BARRA | E18: =IFERROR(VLOOKUP(A18, 'Tabela de preços'!A:D, 4, FALSE), 0) -> 66.45 | F18: =C18*E18 -> 199.35
A19: PKT100064IN | B19: =IFERROR(VLOOKUP(A19, 'Tabela de preços'!A:D, 2, FALSE), "") -> FUNDO ACABAMENTO BRILHO 0 MILESSI | C19: 1 | D19: =IFERROR(VLOOKUP(A19, 'Tabela de preços'!A:D, 3, FALSE), "") -> LT | E19: =IFERROR(VLOOKUP(A19, 'Tabela de preços'!A:D, 4, FALSE), 0) -> 87.7068 | F19: =C19*E19 -> 87.7068
A20: PKT100039IN | B20: =IFERROR(VLOOKUP(A20, 'Tabela de preços'!A:D, 2, FALSE), "") -> COLA PUR TEKBOND 500G | C20: 1 | D20: =IFERROR(VLOOKUP(A20, 'Tabela de preços'!A:D, 3, FALSE), "") -> UNID | E20: =IFERROR(VLOOKUP(A20, 'Tabela de preços'!A:D, 4, FALSE), 0) -> 33.64 | F20: =C20*E20 -> 33.64
A21: PKT100504IN | B21: =IFERROR(VLOOKUP(A21, 'Tabela de preços'!A:D, 2, FALSE), "") -> GRAMPO TIPO ''U'' 80x12MM | C21: 1 | D21: =IFERROR(VLOOKUP(A21, 'Tabela de preços'!A:D, 3, FALSE), "") -> CT | E21: =IFERROR(VLOOKUP(A21, 'Tabela de preços'!A:D, 4, FALSE), 0) -> 2 | F21: =C21*E21 -> 2
A22: PKT100218IN | B22: =IFERROR(VLOOKUP(A22, 'Tabela de preços'!A:D, 2, FALSE), "") -> PINO F30 P/ PINADOR PNEUMATICO | C22: 1 | D22: =IFERROR(VLOOKUP(A22, 'Tabela de preços'!A:D, 3, FALSE), "") -> CT | E22: =IFERROR(VLOOKUP(A22, 'Tabela de preços'!A:D, 4, FALSE), 0) -> 0.452 | F22: =C22*E22 -> 0.452
A23: INSUMOS DE OBRA
A24: PKT100521IN | B24: =IFERROR(VLOOKUP(A24, 'Tabela de preços'!A:D, 2, FALSE), "") -> PARAFUSO BICROMATIZADO PHILIPS 6.0X80MM | C24: 0.2 | D24: =IFERROR(VLOOKUP(A24, 'Tabela de preços'!A:D, 3, FALSE), "") -> CT | E24: =IFERROR(VLOOKUP(A24, 'Tabela de preços'!A:D, 4, FALSE), 0) -> 28 | F24: =C24*E24 -> 5.6
A25: PKT100024IN | B25: =IFERROR(VLOOKUP(A25, 'Tabela de preços'!A:D, 2, FALSE), "") -> BUCHA 08MM | C25: 0.2 | D25: =IFERROR(VLOOKUP(A25, 'Tabela de preços'!A:D, 3, FALSE), "") -> CT | E25: =IFERROR(VLOOKUP(A25, 'Tabela de preços'!A:D, 4, FALSE), 0) -> 18 | F25: =C25*E25 -> 3.6
E27: CUSTO TOTAL DA PORTA: | F27: =SUM(F5:F25) -> 3622.0238

Sheet PT PASSAGEM WC 3D
A1: COMPOSIÇÃO DE CUSTOS - PT PASSAGEM WC 3D
A2: Estrutura de custos por item integrada dinamicamente à Tabela de Preços
A4: CÓDIGO ITEM | B4: DESCRIÇÃO DO ITEM | C4: QUANTIDADE | D4: UNID MEDIDA | E4: CUSTO UNITÁRIO (R$) | F4: CUSTO TOTAL (R$)
A5: FERRAGENS
A6: PKT100513IN | B6: =IFERROR(VLOOKUP(A6, 'Tabela de preços'!A:D, 2, FALSE), "") -> DOBRADIÇA INVISIVEL IN1200 120KG INOX FOSCO 923.03.250 | C6: 4 | D6: =IFERROR(VLOOKUP(A6, 'Tabela de preços'!A:D, 3, FALSE), "") -> UNID | E6: =IFERROR(VLOOKUP(A6, 'Tabela de preços'!A:D, 4, FALSE), 0) -> 416.11 | F6: =C6*E6 -> 1664.44
A7: PKT100050IN | B7: =IFERROR(VLOOKUP(A7, 'Tabela de preços'!A:D, 2, FALSE), "") -> VEDA FRESTAS 04 X 09MM MARROM CLARO C/ 06 MT | C7: 1 | D7: =IFERROR(VLOOKUP(A7, 'Tabela de preços'!A:D, 3, FALSE), "") -> UNID | E7: =IFERROR(VLOOKUP(A7, 'Tabela de preços'!A:D, 4, FALSE), 0) -> 18.51 | F7: =C7*E7 -> 18.51
A8: PKT100070IN | B8: =IFERROR(VLOOKUP(A8, 'Tabela de preços'!A:D, 2, FALSE), "") -> IMÃ 22X10 N.42 | C8: 4 | D8: =IFERROR(VLOOKUP(A8, 'Tabela de preços'!A:D, 3, FALSE), "") -> UNID | E8: =IFERROR(VLOOKUP(A8, 'Tabela de preços'!A:D, 4, FALSE), 0) -> 22.5 | F8: =C8*E8 -> 90
A9: PKT100505IN | B9: =IFERROR(VLOOKUP(A9, 'Tabela de preços'!A:D, 2, FALSE), "") -> FECHADURA AUX LINGUETA RETA INOX FOSCO 911.22.490 | C9: 1 | D9: =IFERROR(VLOOKUP(A9, 'Tabela de preços'!A:D, 3, FALSE), "") -> UNID | E9: =IFERROR(VLOOKUP(A9, 'Tabela de preços'!A:D, 4, FALSE), 0) -> 105.204 | F9: =C9*E9 -> 105.204
A10: PKT100506IN | B10: =IFERROR(VLOOKUP(A10, 'Tabela de preços'!A:D, 2, FALSE), "") -> ADAPTADOR P/WC ZMK NIQ 911.03.885 | C10: 1 | D10: =IFERROR(VLOOKUP(A10, 'Tabela de preços'!A:D, 3, FALSE), "") -> UNID | E10: =IFERROR(VLOOKUP(A10, 'Tabela de preços'!A:D, 4, FALSE), 0) -> 19.12 | F10: =C10*E10 -> 19.12
A11: PKT100512IN | B11: =IFERROR(VLOOKUP(A11, 'Tabela de preços'!A:D, 2, FALSE), "") -> TRANQUETA GOTINHA AÇO INOX ESCOVADO | C11: 2 | D11: =IFERROR(VLOOKUP(A11, 'Tabela de preços'!A:D, 3, FALSE), "") -> UNID | E11: =IFERROR(VLOOKUP(A11, 'Tabela de preços'!A:D, 4, FALSE), 0) -> 293 | F11: =C11*E11 -> 586
A12: MATÉRIA PRIMA
A13: PKT100520IN | B13: =IFERROR(VLOOKUP(A13, 'Tabela de preços'!A:D, 2, FALSE), "") -> COMPENSADO NAVAL 10MM (10X1200X3000) | C13: 2 | D13: =IFERROR(VLOOKUP(A13, 'Tabela de preços'!A:D, 3, FALSE), "") -> UNID | E13: =IFERROR(VLOOKUP(A13, 'Tabela de preços'!A:D, 4, FALSE), 0) -> 185 | F13: =C13*E13 -> 370
A14: PKT-MAT-865 | B14: =IFERROR(VLOOKUP(A14, 'Tabela de preços'!A:D, 2, FALSE), "") -> LAMINA NATURAL CARVALHO EUROPEU | C14: 20 | D14: =IFERROR(VLOOKUP(A14, 'Tabela de preços'!A:D, 3, FALSE), "") -> M² | E14: =IFERROR(VLOOKUP(A14, 'Tabela de preços'!A:D, 4, FALSE), 0) -> 65 | F14: =C14*E14 -> 1300
A15: PKT400351P | B15: =IFERROR(VLOOKUP(A15, 'Tabela de preços'!A:D, 2, FALSE), "") -> MADEIRA MACIÇA TAUARI (0.02X0.30X3.00) | C15: 5 | D15: =IFERROR(VLOOKUP(A15, 'Tabela de preços'!A:D, 3, FALSE), "") -> UNID | E15: =IFERROR(VLOOKUP(A15, 'Tabela de preços'!A:D, 4, FALSE), 0) -> 52.2 | F15: =C15*E15 -> 261
A16: PKT100520IN | B16: =IFERROR(VLOOKUP(A16, 'Tabela de preços'!A:D, 2, FALSE), "") -> COMPENSADO NAVAL 10MM (10X1200X3000) | C16: 1.56 | D16: =IFERROR(VLOOKUP(A16, 'Tabela de preços'!A:D, 3, FALSE), "") -> UNID | E16: =IFERROR(VLOOKUP(A16, 'Tabela de preços'!A:D, 4, FALSE), 0) -> 185 | F16: =C16*E16 -> 288.6
A17: PKT100066IN | B17: =IFERROR(VLOOKUP(A17, 'Tabela de preços'!A:D, 2, FALSE), "") -> COLA TITE BOND 1KG | C17: 1.6 | D17: =IFERROR(VLOOKUP(A17, 'Tabela de preços'!A:D, 3, FALSE), "") -> UNID | E17: =IFERROR(VLOOKUP(A17, 'Tabela de preços'!A:D, 4, FALSE), 0) -> 50.76 | F17: =C17*E17 -> 81.216
A18: PKT100487IN | B18: =IFERROR(VLOOKUP(A18, 'Tabela de preços'!A:D, 2, FALSE), "") -> BARRA TUBO 20 X 30 X 6,00 CH PRETO | C18: 3 | D18: =IFERROR(VLOOKUP(A18, 'Tabela de preços'!A:D, 3, FALSE), "") -> BARRA | E18: =IFERROR(VLOOKUP(A18, 'Tabela de preços'!A:D, 4, FALSE), 0) -> 66.45 | F18: =C18*E18 -> 199.35
A19: PKT100064IN | B19: =IFERROR(VLOOKUP(A19, 'Tabela de preços'!A:D, 2, FALSE), "") -> FUNDO ACABAMENTO BRILHO 0 MILESSI | C19: 1 | D19: =IFERROR(VLOOKUP(A19, 'Tabela de preços'!A:D, 3, FALSE), "") -> LT | E19: =IFERROR(VLOOKUP(A19, 'Tabela de preços'!A:D, 4, FALSE), 0) -> 87.7068 | F19: =C19*E19 -> 87.7068
A20: PKT100039IN | B20: =IFERROR(VLOOKUP(A20, 'Tabela de preços'!A:D, 2, FALSE), "") -> COLA PUR TEKBOND 500G | C20: 1 | D20: =IFERROR(VLOOKUP(A20, 'Tabela de preços'!A:D, 3, FALSE), "") -> UNID | E20: =IFERROR(VLOOKUP(A20, 'Tabela de preços'!A:D, 4, FALSE), 0) -> 33.64 | F20: =C20*E20 -> 33.64
A21: PKT100504IN | B21: =IFERROR(VLOOKUP(A21, 'Tabela de preços'!A:D, 2, FALSE), "") -> GRAMPO TIPO ''U'' 80x12MM | C21: 1 | D21: =IFERROR(VLOOKUP(A21, 'Tabela de preços'!A:D, 3, FALSE), "") -> CT | E21: =IFERROR(VLOOKUP(A21, 'Tabela de preços'!A:D, 4, FALSE), 0) -> 2 | F21: =C21*E21 -> 2
A22: PKT100218IN | B22: =IFERROR(VLOOKUP(A22, 'Tabela de preços'!A:D, 2, FALSE), "") -> PINO F30 P/ PINADOR PNEUMATICO | C22: 1 | D22: =IFERROR(VLOOKUP(A22, 'Tabela de preços'!A:D, 3, FALSE), "") -> CT | E22: =IFERROR(VLOOKUP(A22, 'Tabela de preços'!A:D, 4, FALSE), 0) -> 0.452 | F22: =C22*E22 -> 0.452
A23: INSUMOS DE OBRA
A24: PKT100521IN | B24: =IFERROR(VLOOKUP(A24, 'Tabela de preços'!A:D, 2, FALSE), "") -> PARAFUSO BICROMATIZADO PHILIPS 6.0X80MM | C24: 0.2 | D24: =IFERROR(VLOOKUP(A24, 'Tabela de preços'!A:D, 3, FALSE), "") -> CT | E24: =IFERROR(VLOOKUP(A24, 'Tabela de preços'!A:D, 4, FALSE), 0) -> 28 | F24: =C24*E24 -> 5.6
A25: PKT100024IN | B25: =IFERROR(VLOOKUP(A25, 'Tabela de preços'!A:D, 2, FALSE), "") -> BUCHA 08MM | C25: 0.2 | D25: =IFERROR(VLOOKUP(A25, 'Tabela de preços'!A:D, 3, FALSE), "") -> CT | E25: =IFERROR(VLOOKUP(A25, 'Tabela de preços'!A:D, 4, FALSE), 0) -> 18 | F25: =C25*E25 -> 3.6
E27: CUSTO TOTAL DA PORTA: | F27: =SUM(F5:F25) -> 5116.4388

Sheet PT PASSAGEM INTERNA 3D
A1: COMPOSIÇÃO DE CUSTOS - PT PASSAGEM INTERNA 3D
A2: Estrutura de custos por item integrada dinamicamente à Tabela de Preços
A4: CÓDIGO ITEM | B4: DESCRIÇÃO DO ITEM | C4: QUANTIDADE | D4: UNID MEDIDA | E4: CUSTO UNITÁRIO (R$) | F4: CUSTO TOTAL (R$)
A5: FERRAGENS
A6: PKT100513IN | B6: =IFERROR(VLOOKUP(A6, 'Tabela de preços'!A:D, 2, FALSE), "") -> DOBRADIÇA INVISIVEL IN1200 120KG INOX FOSCO 923.03.250 | C6: 4 | D6: =IFERROR(VLOOKUP(A6, 'Tabela de preços'!A:D, 3, FALSE), "") -> UNID | E6: =IFERROR(VLOOKUP(A6, 'Tabela de preços'!A:D, 4, FALSE), 0) -> 416.11 | F6: =C6*E6 -> 1664.44
A7: PKT100050IN | B7: =IFERROR(VLOOKUP(A7, 'Tabela de preços'!A:D, 2, FALSE), "") -> VEDA FRESTAS 04 X 09MM MARROM CLARO C/ 06 MT | C7: 1 | D7: =IFERROR(VLOOKUP(A7, 'Tabela de preços'!A:D, 3, FALSE), "") -> UNID | E7: =IFERROR(VLOOKUP(A7, 'Tabela de preços'!A:D, 4, FALSE), 0) -> 18.51 | F7: =C7*E7 -> 18.51
A8: PKT100070IN | B8: =IFERROR(VLOOKUP(A8, 'Tabela de preços'!A:D, 2, FALSE), "") -> IMÃ 22X10 N.42 | C8: 4 | D8: =IFERROR(VLOOKUP(A8, 'Tabela de preços'!A:D, 3, FALSE), "") -> UNID | E8: =IFERROR(VLOOKUP(A8, 'Tabela de preços'!A:D, 4, FALSE), 0) -> 22.5 | F8: =C8*E8 -> 90
A9: PKT100505IN | B9: =IFERROR(VLOOKUP(A9, 'Tabela de preços'!A:D, 2, FALSE), "") -> FECHADURA AUX LINGUETA RETA INOX FOSCO 911.22.490 | C9: 1 | D9: =IFERROR(VLOOKUP(A9, 'Tabela de preços'!A:D, 3, FALSE), "") -> UNID | E9: =IFERROR(VLOOKUP(A9, 'Tabela de preços'!A:D, 4, FALSE), 0) -> 105.204 | F9: =C9*E9 -> 105.204
A10: PKT100519IN | B10: =IFERROR(VLOOKUP(A10, 'Tabela de preços'!A:D, 2, FALSE), "") -> ADAPTADOR INTERNO, PARA FECHADURAS COD 911.03.886 | C10: 1 | D10: =IFERROR(VLOOKUP(A10, 'Tabela de preços'!A:D, 3, FALSE), "") -> UNID | E10: =IFERROR(VLOOKUP(A10, 'Tabela de preços'!A:D, 4, FALSE), 0) -> 33.26 | F10: =C10*E10 -> 33.26
A11: PKT100522IN | B11: =IFERROR(VLOOKUP(A11, 'Tabela de preços'!A:D, 2, FALSE), "") -> COLAR OBLONGO ACABAMENTO CHAVE 27,5x13mm | C11: 2 | D11: =IFERROR(VLOOKUP(A11, 'Tabela de preços'!A:D, 3, FALSE), "") -> UNID | E11: =IFERROR(VLOOKUP(A11, 'Tabela de preços'!A:D, 4, FALSE), 0) -> 40 | F11: =C11*E11 -> 80
A12: MATÉRIA PRIMA
A13: PKT100520IN | B13: =IFERROR(VLOOKUP(A13, 'Tabela de preços'!A:D, 2, FALSE), "") -> COMPENSADO NAVAL 10MM (10X1200X3000) | C13: 2 | D13: =IFERROR(VLOOKUP(A13, 'Tabela de preços'!A:D, 3, FALSE), "") -> UNID | E13: =IFERROR(VLOOKUP(A13, 'Tabela de preços'!A:D, 4, FALSE), 0) -> 185 | F13: =C13*E13 -> 370
A14: PKT-MAT-865 | B14: =IFERROR(VLOOKUP(A14, 'Tabela de preços'!A:D, 2, FALSE), "") -> LAMINA NATURAL CARVALHO EUROPEU | C14: 20 | D14: =IFERROR(VLOOKUP(A14, 'Tabela de preços'!A:D, 3, FALSE), "") -> M² | E14: =IFERROR(VLOOKUP(A14, 'Tabela de preços'!A:D, 4, FALSE), 0) -> 65 | F14: =C14*E14 -> 1300
A15: PKT400351P | B15: =IFERROR(VLOOKUP(A15, 'Tabela de preços'!A:D, 2, FALSE), "") -> MADEIRA MACIÇA TAUARI (0.02X0.30X3.00) | C15: 5 | D15: =IFERROR(VLOOKUP(A15, 'Tabela de preços'!A:D, 3, FALSE), "") -> UNID | E15: =IFERROR(VLOOKUP(A15, 'Tabela de preços'!A:D, 4, FALSE), 0) -> 52.2 | F15: =C15*E15 -> 261
A16: PKT100520IN | B16: =IFERROR(VLOOKUP(A16, 'Tabela de preços'!A:D, 2, FALSE), "") -> COMPENSADO NAVAL 10MM (10X1200X3000) | C16: 1.56 | D16: =IFERROR(VLOOKUP(A16, 'Tabela de preços'!A:D, 3, FALSE), "") -> UNID | E16: =IFERROR(VLOOKUP(A16, 'Tabela de preços'!A:D, 4, FALSE), 0) -> 185 | F16: =C16*E16 -> 288.6
A17: PKT100066IN | B17: =IFERROR(VLOOKUP(A17, 'Tabela de preços'!A:D, 2, FALSE), "") -> COLA TITE BOND 1KG | C17: 1.6 | D17: =IFERROR(VLOOKUP(A17, 'Tabela de preços'!A:D, 3, FALSE), "") -> UNID | E17: =IFERROR(VLOOKUP(A17, 'Tabela de preços'!A:D, 4, FALSE), 0) -> 50.76 | F17: =C17*E17 -> 81.216
A18: PKT100487IN | B18: =IFERROR(VLOOKUP(A18, 'Tabela de preços'!A:D, 2, FALSE), "") -> BARRA TUBO 20 X 30 X 6,00 CH PRETO | C18: 3 | D18: =IFERROR(VLOOKUP(A18, 'Tabela de preços'!A:D, 3, FALSE), "") -> BARRA | E18: =IFERROR(VLOOKUP(A18, 'Tabela de preços'!A:D, 4, FALSE), 0) -> 66.45 | F18: =C18*E18 -> 199.35
A19: PKT100064IN | B19: =IFERROR(VLOOKUP(A19, 'Tabela de preços'!A:D, 2, FALSE), "") -> FUNDO ACABAMENTO BRILHO 0 MILESSI | C19: 1 | D19: =IFERROR(VLOOKUP(A19, 'Tabela de preços'!A:D, 3, FALSE), "") -> LT | E19: =IFERROR(VLOOKUP(A19, 'Tabela de preços'!A:D, 4, FALSE), 0) -> 87.7068 | F19: =C19*E19 -> 87.7068
A20: PKT100039IN | B20: =IFERROR(VLOOKUP(A20, 'Tabela de preços'!A:D, 2, FALSE), "") -> COLA PUR TEKBOND 500G | C20: 1 | D20: =IFERROR(VLOOKUP(A20, 'Tabela de preços'!A:D, 3, FALSE), "") -> UNID | E20: =IFERROR(VLOOKUP(A20, 'Tabela de preços'!A:D, 4, FALSE), 0) -> 33.64 | F20: =C20*E20 -> 33.64
A21: PKT100504IN | B21: =IFERROR(VLOOKUP(A21, 'Tabela de preços'!A:D, 2, FALSE), "") -> GRAMPO TIPO ''U'' 80x12MM | C21: 1 | D21: =IFERROR(VLOOKUP(A21, 'Tabela de preços'!A:D, 3, FALSE), "") -> CT | E21: =IFERROR(VLOOKUP(A21, 'Tabela de preços'!A:D, 4, FALSE), 0) -> 2 | F21: =C21*E21 -> 2
A22: PKT100218IN | B22: =IFERROR(VLOOKUP(A22, 'Tabela de preços'!A:D, 2, FALSE), "") -> PINO F30 P/ PINADOR PNEUMATICO | C22: 1 | D22: =IFERROR(VLOOKUP(A22, 'Tabela de preços'!A:D, 3, FALSE), "") -> CT | E22: =IFERROR(VLOOKUP(A22, 'Tabela de preços'!A:D, 4, FALSE), 0) -> 0.452 | F22: =C22*E22 -> 0.452
A23: INSUMOS DE OBRA
